Workbook
Name Slicer_Item: #N/A
Name Slicer_Month: #N/A
Name Slicer_Month1: #N/A
Name Slicer_Month2: #N/A
Name Slicer_Spent_Group: #N/A

Sheet dirty_cafe_sales_raw
A1: Transaction ID | B1: Item | C1: Quantity | D1: Price Per Unit | E1: Total Spent | F1: Payment Method | G1: Location | H1: Transaction Date
A2: TXN_1961373 | B2: Coffee | C2: 2 | D2: 2 | E2: 4 | F2: Credit Card | G2: Takeaway | H2: 45177
A3: TXN_4977031 | B3: Cake | C3: 4 | D3: 3 | E3: 12 | F3: Cash | G3: In-store | H3: 45062
A4: TXN_4271903 | B4: Cookie | C4: 4 | D4: 1 | E4: ERROR | F4: Credit Card | G4: In-store | H4: 45126
A5: TXN_7034554 | B5: Salad | C5: 2 | D5: 5 | E5: 10 | F5: UNKNOWN | G5: UNKNOWN | H5: 45043
A6: TXN_3160411 | B6: Coffee | C6: 2 | D6: 2 | E6: 4 | F6: Digital Wallet | G6: In-store | H6: 45088
A7: TXN_2602893 | B7: Smoothie | C7: 5 | D7: 4 | E7: 20 | F7: Credit Card | H7: 45016
A8: TXN_4433211 | B8: UNKNOWN | C8: 3 | D8: 3 | E8: 9 | F8: ERROR | G8: Takeaway | H8: 45205
A9: TXN_6699534 | B9: Sandwich | C9: 4 | D9: 4 | E9: 16 | F9: Cash | G9: UNKNOWN | H9: 45227
A10: TXN_4717867 | C10: 5 | D10: 3 | E10: 15 | G10: Takeaway | H10: 45135
A11: TXN_2064365 | B11: Sandwich | C11: 5 | D11: 4 | E11: 20 | G11: In-store | H11: 45291
A12: TXN_2548360 | B12: Salad | C12: 5 | D12: 5 | E12: 25 | F12: Cash | G12: Takeaway | H12: 45237
A13: TXN_3051279 | B13: Sandwich | C13: 2 | D13: 4 | E13: 8 | F13: Credit Card | G13: Takeaway | H13: ERROR
A14: TXN_7619095 | B14: Sandwich | C14: 2 | D14: 4 | E14: 8 | F14: Cash | G14: In-store | H14: 45049
A15: TXN_9437049 | B15: Cookie | C15: 5 | D15: 1 | E15: 5 | G15: Takeaway | H15: 45078
A16: TXN_8915701 | B16: ERROR | C16: 2 | D16: 1.5 | E16: 3 | G16: In-store | H16: 45006
A17: TXN_2847255 | B17: Salad | C17: 3 | D17: 5 | E17: 15 | F17: Credit Card | G17: In-store | H17: 45245
A18: TXN_3765707 | B18: Sandwich | C18: 1 | D18: 4 | E18: 4 | H18: 45087
A19: TXN_6769710 | B19: Juice | C19: 2 | D19: 3 | E19: 6 | F19: Cash | G19: In-store | H19: 44981
A20: TXN_8876618 | B20: Cake | C20: 5 | D20: 3 | E20: 15 | F20: Cash | G20: ERROR | H20: 45010
A21: TXN_3709394 | B21: Juice | C21: 4 | D21: 3 | E21: 12 | F21: Cash | G21: Takeaway | H21: 44941
A22: TXN_3522028 | B22: Smoothie | C22: ERROR | D22: 4 | E22: 20 | F22: Cash | G22: In-store | H22: 45020
A23: TXN_3567645 | B23: Smoothie | C23: 4 | D23: 4 | E23: 16 | F23: Credit Card | G23: Takeaway | H23: 45015
A24: TXN_5132361 | B24: Sandwich | C24: 3 | D24: 4 | E24: 12 | F24: Digital Wallet | G24: Takeaway | H24: 45261
A25: TXN_2616390 | B25: Sandwich | C25: 2 | D25: 4 | E25: 8 | H25: 45187
A26: TXN_9400181 | B26: Sandwich | C26: 5 | D26: 4 | E26: 20 | F26: Cash | G26: In-store | H26: 45080
A27: TXN_7958992 | B27: Smoothie | C27: 3 | D27: 4 | F27: UNKNOWN | G27: UNKNOWN | H27: 45273
A28: TXN_5183041 | B28: Cookie | C28: 5 | D28: 1 | E28: 5 | F28: Credit Card | G28: In-store | H28: 45036
A29: TXN_5695074 | B29: Juice | C29: 4 | D29: 3 | E29: 12 | F29: Credit Card | G29: Takeaway | H29: 45026
A30: TXN_8467949 | B30: Smoothie | C30: 5 | D30: 4 | E30: 20 | F30: Credit Card | H30: 44996
A31: TXN_7640952 | B31: Cake | C31: 4 | D31: 3 | E31: 12 | F31: Digital Wallet | G31: Takeaway | H31: ERROR
A32: TXN_1736287 | C32: 5 | D32: 2 | E32: 10 | F32: Digital Wallet | H32: 45079
A33: TXN_8927252 | B33: UNKNOWN | C33: 2 | D33: 1 | E33: ERROR | F33: Credit Card | G33: ERROR | H33: 45236
A34: TXN_9677376 | B34: Smoothie | C34: 4 | D34: 4 | E34: 16 | G34: In-store | H34: 45153
A35: TXN_7710508 | B35: UNKNOWN | C35: 5 | D35: 1 | E35: 5 | F35: Cash | H35: ERROR
A36: TXN_8853997 | B36: Smoothie | C36: 2 | D36: 4 | E36: 8 | F36: Digital Wallet | G36: Takeaway | H36: 45208
A37: TXN_9130559 | B37: Sandwich | C37: 1 | D37: 4 | E37: 4 | F37: Credit Card | G37: UNKNOWN | H37: 45074
A38: TXN_6855453 | B38: UNKNOWN | C38: 4 | D38: 3 | E38: 12 | G38: In-store | H38: 45124
A39: TXN_1080432 | B39: Salad | C39: 2 | D39: 5 | E39: 10 | F39: Credit Card | G39: In-store | H39: 45045
A40: TXN_2655815 | B40: Smoothie | C40: 4 | D40: 4 | E40: 16 | G40: Takeaway | H40: 45085
...

Sheet Working Sheet
A1: Item | B1: Quantity | C1: Price Per Unit | D1: Total Spent | E1: Spent Group | F1: Payment Method | G1: Location | H1: Transaction Date | I1: Year | J1: Month | K1: Day | L1: Days of the week | M1: Transcation Complete?
A2: Salad | B2: =$D2/$C2 -> 2 | C2: 5 | D2: 10 | E2: {=_xlfn.IFS(D2<=5, "$1-5", D2<=10, "$6-10",D2<=15,"$11-15", D2<=20, "$16-20", D2>20, "$20+")} -> $6-10 | F2: Unspecified | G2: Unspecified | H2: 44927 | I2: =IFERROR(YEAR(H2), "N/A") -> 2023 | J2: {=IFERROR(TEXT(H2, "[$-en-US]mmm"), _xleta.N/A)} -> Jan | K2: =IFERROR(DAY(H2), "N/A") -> 1 | L2: =IFERROR(TEXT(K2, "[$-en-US]dddd"), "N/A") -> Sunday | M2: =IF(AND(H2="Error",F2="Error"), "No","Yes") -> Yes
A3: Cake | B3: =$D3/$C3 -> 3 | C3: 3 | D3: 9 | E3: {=_xlfn.IFS(D3<=5, "$1-5", D3<=10, "$6-10",D3<=15,"$11-15", D3<=20, "$16-20", D3>20, "$20+")} -> $6-10 | F3: Error | G3: In-store | H3: 44927 | I3: =IFERROR(YEAR(H3), "N/A") -> 2023 | J3: {=IFERROR(TEXT(H3, "[$-en-US]mmm"), _xleta.N/A)} -> Jan | K3: =IFERROR(DAY(H3), "N/A") -> 1 | L3: =IFERROR(TEXT(K3, "[$-en-US]dddd"), "N/A") -> Sunday | M3: =IF(AND(H3="Error",F3="Error"), "No","Yes") -> Yes
A4: Sandwich | B4: 5 | C4: =$D4/$B4 -> 4 | D4: 20 | E4: {=_xlfn.IFS(D4<=5, "$1-5", D4<=10, "$6-10",D4<=15,"$11-15", D4<=20, "$16-20", D4>20, "$20+")} -> $16-20 | F4: Digital Wallet | G4: In-store | H4: 44927 | I4: =IFERROR(YEAR(H4), "N/A") -> 2023 | J4: {=IFERROR(TEXT(H4, "[$-en-US]mmm"), _xleta.N/A)} -> Jan | K4: =IFERROR(DAY(H4), "N/A") -> 1 | L4: =IFERROR(TEXT(K4, "[$-en-US]dddd"), "N/A") -> Sunday | M4: =IF(AND(H4="Error",F4="Error"), "No","Yes") -> Yes
A5: Juice | B5: 5 | C5: 3 | D5: 15 | E5: {=_xlfn.IFS(D5<=5, "$1-5", D5<=10, "$6-10",D5<=15,"$11-15", D5<=20, "$16-20", D5>20, "$20+")} -> $11-15 | F5: Digital Wallet | G5: Takeaway | H5: 44927 | I5: =IFERROR(YEAR(H5), "N/A") -> 2023 | J5: {=IFERROR(TEXT(H5, "[$-en-US]mmm"), _xleta.N/A)} -> Jan | K5: =IFERROR(DAY(H5), "N/A") -> 1 | L5: =IFERROR(TEXT(K5, "[$-en-US]dddd"), "N/A") -> Sunday | M5: =IF(AND(H5="Error",F5="Error"), "No","Yes") -> Yes
A6: Sandwich | B6: 5 | C6: 4 | D6: 20 | E6: {=_xlfn.IFS(D6<=5, "$1-5", D6<=10, "$6-10",D6<=15,"$11-15", D6<=20, "$16-20", D6>20, "$20+")} -> $16-20 | F6: Cash | G6: In-store | H6: 44927 | I6: =IFERROR(YEAR(H6), "N/A") -> 2023 | J6: {=IFERROR(TEXT(H6, "[$-en-US]mmm"), _xleta.N/A)} -> Jan | K6: =IFERROR(DAY(H6), "N/A") -> 1 | L6: =IFERROR(TEXT(K6, "[$-en-US]dddd"), "N/A") -> Sunday | M6: =IF(AND(H6="Error",F6="Error"), "No","Yes") -> Yes
A7: Tea | B7: 3 | C7: 1.5 | D7: 4.5 | E7: {=_xlfn.IFS(D7<=5, "$1-5", D7<=10, "$6-10",D7<=15,"$11-15", D7<=20, "$16-20", D7>20, "$20+")} -> $1-5 | F7: Digital Wallet | G7: In-store | H7: 44927 | I7: =IFERROR(YEAR(H7), "N/A") -> 2023 | J7: {=IFERROR(TEXT(H7, "[$-en-US]mmm"), _xleta.N/A)} -> Jan | K7: =IFERROR(DAY(H7), "N/A") -> 1 | L7: =IFERROR(TEXT(K7, "[$-en-US]dddd"), "N/A") -> Sunday | M7: =IF(AND(H7="Error",F7="Error"), "No","Yes") -> Yes
A8: Salad | B8: 2 | C8: 5 | D8: 10 | E8: {=_xlfn.IFS(D8<=5, "$1-5", D8<=10, "$6-10",D8<=15,"$11-15", D8<=20, "$16-20", D8>20, "$20+")} -> $6-10 | F8: Digital Wallet | G8: Takeaway | H8: 44927 | I8: =IFERROR(YEAR(H8), "N/A") -> 2023 | J8: {=IFERROR(TEXT(H8, "[$-en-US]mmm"), _xleta.N/A)} -> Jan | K8: =IFERROR(DAY(H8), "N/A") -> 1 | L8: =IFERROR(TEXT(K8, "[$-en-US]dddd"), "N/A") -> Sunday | M8: =IF(AND(H8="Error",F8="Error"), "No","Yes") -> Yes
A9: Coffee | B9: 5 | C9: 2 | D9: 10 | E9: {=_xlfn.IFS(D9<=5, "$1-5", D9<=10, "$6-10",D9<=15,"$11-15", D9<=20, "$16-20", D9>20, "$20+")} -> $6-10 | F9: Digital Wallet | G9: Error | H9: 44927 | I9: =IFERROR(YEAR(H9), "N/A") -> 2023 | J9: {=IFERROR(TEXT(H9, "[$-en-US]mmm"), _xleta.N/A)} -> Jan | K9: =IFERROR(DAY(H9), "N/A") -> 1 | L9: =IFERROR(TEXT(K9, "[$-en-US]dddd"), "N/A") -> Sunday | M9: =IF(AND(H9="Error",F9="Error"), "No","Yes") -> Yes
A10: Unspecified | B10: 4 | C10: 3 | D10: 12 | E10: {=_xlfn.IFS(D10<=5, "$1-5", D10<=10, "$6-10",D10<=15,"$11-15", D10<=20, "$16-20", D10>20, "$20+")} -> $11-15 | F10: Unspecified | G10: Unspecified | H10: 44927 | I10: =IFERROR(YEAR(H10), "N/A") -> 2023 | J10: {=IFERROR(TEXT(H10, "[$-en-US]mmm"), _xleta.N/A)} -> Jan | K10: =IFERROR(DAY(H10), "N/A") -> 1 | L10: =IFERROR(TEXT(K10, "[$-en-US]dddd"), "N/A") -> Sunday | M10: =IF(AND(H10="Error",F10="Error"), "No","Yes") -> Yes
A11: Sandwich | B11: 1 | C11: 4 | D11: 4 | E11: {=_xlfn.IFS(D11<=5, "$1-5", D11<=10, "$6-10",D11<=15,"$11-15", D11<=20, "$16-20", D11>20, "$20+")} -> $1-5 | F11: Digital Wallet | G11: In-store | H11: 44927 | I11: =IFERROR(YEAR(H11), "N/A") -> 2023 | J11: {=IFERROR(TEXT(H11, "[$-en-US]mmm"), _xleta.N/A)} -> Jan | K11: =IFERROR(DAY(H11), "N/A") -> 1 | L11: =IFERROR(TEXT(K11, "[$-en-US]dddd"), "N/A") -> Sunday | M11: =IF(AND(H11="Error",F11="Error"), "No","Yes") -> Yes
A12: Cake | B12: 4 | C12: 3 | D12: 12 | E12: {=_xlfn.IFS(D12<=5, "$1-5", D12<=10, "$6-10",D12<=15,"$11-15", D12<=20, "$16-20", D12>20, "$20+")} -> $11-15 | F12: Cash | G12: Takeaway | H12: 44927 | I12: =IFERROR(YEAR(H12), "N/A") -> 2023 | J12: {=IFERROR(TEXT(H12, "[$-en-US]mmm"), _xleta.N/A)} -> Jan | K12: =IFERROR(DAY(H12), "N/A") -> 1 | L12: =IFERROR(TEXT(K12, "[$-en-US]dddd"), "N/A") -> Sunday | M12: =IF(AND(H12="Error",F12="Error"), "No","Yes") -> Yes
A13: Coffee | B13: 4 | C13: 2 | D13: 8 | E13: {=_xlfn.IFS(D13<=5, "$1-5", D13<=10, "$6-10",D13<=15,"$11-15", D13<=20, "$16-20", D13>20, "$20+")} -> $6-10 | F13: Digital Wallet | G13: In-store | H13: 44927 | I13: =IFERROR(YEAR(H13), "N/A") -> 2023 | J13: {=IFERROR(TEXT(H13, "[$-en-US]mmm"), _xleta.N/A)} -> Jan | K13: =IFERROR(DAY(H13), "N/A") -> 1 | L13: =IFERROR(TEXT(K13, "[$-en-US]dddd"), "N/A") -> Sunday | M13: =IF(AND(H13="Error",F13="Error"), "No","Yes") -> Yes
A14: Coffee | B14: =$D14/$C14 -> 1 | C14: 2 | D14: 2 | E14: {=_xlfn.IFS(D14<=5, "$1-5", D14<=10, "$6-10",D14<=15,"$11-15", D14<=20, "$16-20", D14>20, "$20+")} -> $1-5 | F14: Credit Card | G14: Unspecified | H14: 44927 | I14: =IFERROR(YEAR(H14), "N/A") -> 2023 | J14: {=IFERROR(TEXT(H14, "[$-en-US]mmm"), _xleta.N/A)} -> Jan | K14: =IFERROR(DAY(H14), "N/A") -> 1 | L14: =IFERROR(TEXT(K14, "[$-en-US]dddd"), "N/A") -> Sunday | M14: =IF(AND(H14="Error",F14="Error"), "No","Yes") -> Yes
A15: Coffee | B15: 2 | C15: 2 | D15: 4 | E15: {=_xlfn.IFS(D15<=5, "$1-5", D15<=10, "$6-10",D15<=15,"$11-15", D15<=20, "$16-20", D15>20, "$20+")} -> $1-5 | F15: Unspecified | G15: Unspecified | H15: 44927 | I15: =IFERROR(YEAR(H15), "N/A") -> 2023 | J15: {=IFERROR(TEXT(H15, "[$-en-US]mmm"), _xleta.N/A)} -> Jan | K15: =IFERROR(DAY(H15), "N/A") -> 1 | L15: =IFERROR(TEXT(K15, "[$-en-US]dddd"), "N/A") -> Sunday | M15: =IF(AND(H15="Error",F15="Error"), "No","Yes") -> Yes
A16: Cookie | B16: 4 | C16: 1 | D16: 4 | E16: {=_xlfn.IFS(D16<=5, "$1-5", D16<=10, "$6-10",D16<=15,"$11-15", D16<=20, "$16-20", D16>20, "$20+")} -> $1-5 | F16: Credit Card | G16: Error | H16: 44927 | I16: =IFERROR(YEAR(H16), "N/A") -> 2023 | J16: {=IFERROR(TEXT(H16, "[$-en-US]mmm"), _xleta.N/A)} -> Jan | K16: =IFERROR(DAY(H16), "N/A") -> 1 | L16: =IFERROR(TEXT(K16, "[$-en-US]dddd"), "N/A") -> Sunday | M16: =IF(AND(H16="Error",F16="Error"), "No","Yes") -> Yes
A17: Tea | B17: 5 | C17: 1.5 | D17: =$B17*$C17 -> 7.5 | E17: {=_xlfn.IFS(D17<=5, "$1-5", D17<=10, "$6-10",D17<=15,"$11-15", D17<=20, "$16-20", D17>20, "$20+")} -> $6-10 | F17: Unspecified | G17: Takeaway | H17: 44927 | I17: =IFERROR(YEAR(H17), "N/A") -> 2023 | J17: {=IFERROR(TEXT(H17, "[$-en-US]mmm"), _xleta.N/A)} -> Jan | K17: =IFERROR(DAY(H17), "N/A") -> 1 | L17: =IFERROR(TEXT(K17, "[$-en-US]dddd"), "N/A") -> Sunday | M17: =IF(AND(H17="Error",F17="Error"), "No","Yes") -> Yes
A18: Juice | B18: 1 | C18: 3 | D18: 3 | E18: {=_xlfn.IFS(D18<=5, "$1-5", D18<=10, "$6-10",D18<=15,"$11-15", D18<=20, "$16-20", D18>20, "$20+")} -> $1-5 | F18: Digital Wallet | G18: Takeaway | H18: 44927 | I18: =IFERROR(YEAR(H18), "N/A") -> 2023 | J18: {=IFERROR(TEXT(H18, "[$-en-US]mmm"), _xleta.N/A)} -> Jan | K18: =IFERROR(DAY(H18), "N/A") -> 1 | L18: =IFERROR(TEXT(K18, "[$-en-US]dddd"), "N/A") -> Sunday | M18: =IF(AND(H18="Error",F18="Error"), "No","Yes") -> Yes
A19: Coffee | B19: 2 | C19: 2 | D19: 4 | E19: {=_xlfn.IFS(D19<=5, "$1-5", D19<=10, "$6-10",D19<=15,"$11-15", D19<=20, "$16-20", D19>20, "$20+")} -> $1-5 | F19: Cash | G19: In-store | H19: 44927 | I19: =IFERROR(YEAR(H19), "N/A") -> 2023 | J19: {=IFERROR(TEXT(H19, "[$-en-US]mmm"), _xleta.N/A)} -> Jan | K19: =IFERROR(DAY(H19), "N/A") -> 1 | L19: =IFERROR(TEXT(K19, "[$-en-US]dddd"), "N/A") -> Sunday | M19: =IF(AND(H19="Error",F19="Error"), "No","Yes") -> Yes
A20: Smoothie | B20: 2 | C20: 4 | D20: 8 | E20: {=_xlfn.IFS(D20<=5, "$1-5", D20<=10, "$6-10",D20<=15,"$11-15", D20<=20, "$16-20", D20>20, "$20+")} -> $6-10 | F20: Digital Wallet | G20: In-store | H20: 44927 | I20: =IFERROR(YEAR(H20), "N/A") -> 2023 | J20: {=IFERROR(TEXT(H20, "[$-en-US]mmm"), _xleta.N/A)} -> Jan | K20: =IFERROR(DAY(H20), "N/A") -> 1 | L20: =IFERROR(TEXT(K20, "[$-en-US]dddd"), "N/A") -> Sunday | M20: =IF(AND(H20="Error",F20="Error"), "No","Yes") -> Yes
A21: Cake | B21: 3 | C21: 3 | D21: 9 | E21: {=_xlfn.IFS(D21<=5, "$1-5", D21<=10, "$6-10",D21<=15,"$11-15", D21<=20, "$16-20", D21>20, "$20+")} -> $6-10 | F21: Digital Wallet | G21: Takeaway | H21: 44927 | I21: =IFERROR(YEAR(H21), "N/A") -> 2023 | J21: {=IFERROR(TEXT(H21, "[$-en-US]mmm"), _xleta.N/A)} -> Jan | K21: =IFERROR(DAY(H21), "N/A") -> 1 | L21: =IFERROR(TEXT(K21, "[$-en-US]dddd"), "N/A") -> Sunday | M21: =IF(AND(H21="Error",F21="Error"), "No","Yes") -> Yes
A22: Sandwich | B22: 5 | C22: 4 | D22: 20 | E22: {=_xlfn.IFS(D22<=5, "$1-5", D22<=10, "$6-10",D22<=15,"$11-15", D22<=20, "$16-20", D22>20, "$20+")} -> $16-20 | F22: Credit Card | G22: In-store | H22: 44928 | I22: =IFERROR(YEAR(H22), "N/A") -> 2023 | J22: {=IFERROR(TEXT(H22, "[$-en-US]mmm"), _xleta.N/A)} -> Jan | K22: =IFERROR(DAY(H22), "N/A") -> 2 | L22: =IFERROR(TEXT(K22, "[$-en-US]dddd"), "N/A") -> Monday | M22: =IF(AND(H22="Error",F22="Error"), "No","Yes") -> Yes
A23: Cookie | B23: 4 | C23: 1 | D23: 4 | E23: {=_xlfn.IFS(D23<=5, "$1-5", D23<=10, "$6-10",D23<=15,"$11-15", D23<=20, "$16-20", D23>20, "$20+")} -> $1-5 | F23: Digital Wallet | G23: In-store | H23: 44928 | I23: =IFERROR(YEAR(H23), "N/A") -> 2023 | J23: {=IFERROR(TEXT(H23, "[$-en-US]mmm"), _xleta.N/A)} -> Jan | K23: =IFERROR(DAY(H23), "N/A") -> 2 | L23: =IFERROR(TEXT(K23, "[$-en-US]dddd"), "N/A") -> Monday | M23: =IF(AND(H23="Error",F23="Error"), "No","Yes") -> Yes
A24: Unspecified | B24: 5 | C24: 4 | D24: 20 | E24: {=_xlfn.IFS(D24<=5, "$1-5", D24<=10, "$6-10",D24<=15,"$11-15", D24<=20, "$16-20", D24>20, "$20+")} -> $16-20 | F24: Credit Card | G24: Unspecified | H24: 44928 | I24: =IFERROR(YEAR(H24), "N/A") -> 2023 | J24: {=IFERROR(TEXT(H24, "[$-en-US]mmm"), _xleta.N/A)} -> Jan | K24: =IFERROR(DAY(H24), "N/A") -> 2 | L24: =IFERROR(TEXT(K24, "[$-en-US]dddd"), "N/A") -> Monday | M24: =IF(AND(H24="Error",F24="Error"), "No","Yes") -> Yes
A25: Smoothie | B25: 1 | C25: 4 | D25: 4 | E25: {=_xlfn.IFS(D25<=5, "$1-5", D25<=10, "$6-10",D25<=15,"$11-15", D25<=20, "$16-20", D25>20, "$20+")} -> $1-5 | F25: Unspecified | G25: Takeaway | H25: 44928 | I25: =IFERROR(YEAR(H25), "N/A") -> 2023 | J25: {=IFERROR(TEXT(H25, "[$-en-US]mmm"), _xleta.N/A)} -> Jan | K25: =IFERROR(DAY(H25), "N/A") -> 2 | L25: =IFERROR(TEXT(K25, "[$-en-US]dddd"), "N/A") -> Monday | M25: =IF(AND(H25="Error",F25="Error"), "No","Yes") -> Yes
A26: Salad | B26: 2 | C26: 5 | D26: 10 | E26: {=_xlfn.IFS(D26<=5, "$1-5", D26<=10, "$6-10",D26<=15,"$11-15", D26<=20, "$16-20", D26>20, "$20+")} -> $6-10 | F26: Unspecified | G26: Unspecified | H26: 44928 | I26: =IFERROR(YEAR(H26), "N/A") -> 2023 | J26: {=IFERROR(TEXT(H26, "[$-en-US]mmm"), _xleta.N/A)} -> Jan | K26: =IFERROR(DAY(H26), "N/A") -> 2 | L26: =IFERROR(TEXT(K26, "[$-en-US]dddd"), "N/A") -> Monday | M26: =IF(AND(H26="Error",F26="Error"), "No","Yes") -> Yes
A27: Sandwich | B27: 5 | C27: 4 | D27: =$B27*$C27 -> 20 | E27: {=_xlfn.IFS(D27<=5, "$1-5", D27<=10, "$6-10",D27<=15,"$11-15", D27<=20, "$16-20", D27>20, "$20+")} -> $16-20 | F27: Credit Card | G27: In-store | H27: 44928 | I27: =IFERROR(YEAR(H27), "N/A") -> 2023 | J27: {=IFERROR(TEXT(H27, "[$-en-US]mmm"), _xleta.N/A)} -> Jan | K27: =IFERROR(DAY(H27), "N/A") -> 2 | L27: =IFERROR(TEXT(K27, "[$-en-US]dddd"), "N/A") -> Monday | M27: =IF(AND(H27="Error",F27="Error"), "No","Yes") -> Yes
A28: Smoothie | B28: =$D28/$C28 -> 5 | C28: 4 | D28: 20 | E28: {=_xlfn.IFS(D28<=5, "$1-5", D28<=10, "$6-10",D28<=15,"$11-15", D28<=20, "$16-20", D28>20, "$20+")} -> $16-20 | F28: Cash | G28: Unspecified | H28: 44928 | I28: =IFERROR(YEAR(H28), "N/A") -> 2023 | J28: {=IFERROR(TEXT(H28, "[$-en-US]mmm"), _xleta.N/A)} -> Jan | K28: =IFERROR(DAY(H28), "N/A") -> 2 | L28: =IFERROR(TEXT(K28, "[$-en-US]dddd"), "N/A") -> Monday | M28: =IF(AND(H28="Error",F28="Error"), "No","Yes") -> Yes
A29: Sandwich | B29: 2 | C29: 4 | D29: =$B29*$C29 -> 8 | E29: {=_xlfn.IFS(D29<=5, "$1-5", D29<=10, "$6-10",D29<=15,"$11-15", D29<=20, "$16-20", D29>20, "$20+")} -> $6-10 | F29: Credit Card | G29: In-store | H29: 44928 | I29: =IFERROR(YEAR(H29), "N/A") -> 2023 | J29: {=IFERROR(TEXT(H29, "[$-en-US]mmm"), _xleta.N/A)} -> Jan | K29: =IFERROR(DAY(H29), "N/A") -> 2 | L29: =IFERROR(TEXT(K29, "[$-en-US]dddd"), "N/A") -> Monday | M29: =IF(AND(H29="Error",F29="Error"), "No","Yes") -> Yes
A30: Cookie | B30: 5 | C30: 1 | D30: 5 | E30: {=_xlfn.IFS(D30<=5, "$1-5", D30<=10, "$6-10",D30<=15,"$11-15", D30<=20, "$16-20", D30>20, "$20+")} -> $1-5 | F30: Credit Card | G30: Unspecified | H30: 44928 | I30: =IFERROR(YEAR(H30), "N/A") -> 2023 | J30: {=IFERROR(TEXT(H30, "[$-en-US]mmm"), _xleta.N/A)} -> Jan | K30: =IFERROR(DAY(H30), "N/A") -> 2 | L30: =IFERROR(TEXT(K30, "[$-en-US]dddd"), "N/A") -> Monday | M30: =IF(AND(H30="Error",F30="Error"), "No","Yes") -> Yes
A31: Cake | B31: 2 | C31: 3 | D31: 6 | E31: {=_xlfn.IFS(D31<=5, "$1-5", D31<=10, "$6-10",D31<=15,"$11-15", D31<=20, "$16-20", D31>20, "$20+")} -> $6-10 | F31: Cash | G31: Takeaway | H31: 44928 | I31: =IFERROR(YEAR(H31), "N/A") -> 2023 | J31: {=IFERROR(TEXT(H31, "[$-en-US]mmm"), _xleta.N/A)} -> Jan | K31: =IFERROR(DAY(H31), "N/A") -> 2 | L31: =IFERROR(TEXT(K31, "[$-en-US]dddd"), "N/A") -> Monday | M31: =IF(AND(H31="Error",F31="Error"), "No","Yes") -> Yes
A32: Smoothie | B32: 2 | C32: 4 | D32: 8 | E32: {=_xlfn.IFS(D32<=5, "$1-5", D32<=10, "$6-10",D32<=15,"$11-15", D32<=20, "$16-20", D32>20, "$20+")} -> $6-10 | F32: Unspecified | G32: In-store | H32: 44928 | I32: =IFERROR(YEAR(H32), "N/A") -> 2023 | J32: {=IFERROR(TEXT(H32, "[$-en-US]mmm"), _xleta.N/A)} -> Jan | K32: =IFERROR(DAY(H32), "N/A") -> 2 | L32: =IFERROR(TEXT(K32, "[$-en-US]dddd"), "N/A") -> Monday | M32: =IF(AND(H32="Error",F32="Error"), "No","Yes") -> Yes
A33: =_xlfn.XLOOKUP(C33,'Item Price'!$B:$B,'Item Price'!$A:$A,"notfound") -> Tea | B33: 2 | C33: 1.5 | D33: 3 | E33: {=_xlfn.IFS(D33<=5, "$1-5", D33<=10, "$6-10",D33<=15,"$11-15", D33<=20, "$16-20", D33>20, "$20+")} -> $1-5 | F33: Credit Card | G33: Takeaway | H33: 44928 | I33: =IFERROR(YEAR(H33), "N/A") -> 2023 | J33: {=IFERROR(TEXT(H33, "[$-en-US]mmm"), _xleta.N/A)} -> Jan | K33: =IFERROR(DAY(H33), "N/A") -> 2 | L33: =IFERROR(TEXT(K33, "[$-en-US]dddd"), "N/A") -> Monday | M33: =IF(AND(H33="Error",F33="Error"), "No","Yes") -> Yes
A34: Cookie | B34: =$D34/$C34 -> 4 | C34: 1 | D34: 4 | E34: {=_xlfn.IFS(D34<=5, "$1-5", D34<=10, "$6-10",D34<=15,"$11-15", D34<=20, "$16-20", D34>20, "$20+")} -> $1-5 | F34: Unspecified | G34: Takeaway | H34: 44928 | I34: =IFERROR(YEAR(H34), "N/A") -> 2023 | J34: {=IFERROR(TEXT(H34, "[$-en-US]mmm"), _xleta.N/A)} -> Jan | K34: =IFERROR(DAY(H34), "N/A") -> 2 | L34: =IFERROR(TEXT(K34, "[$-en-US]dddd"), "N/A") -> Monday | M34: =IF(AND(H34="Error",F34="Error"), "No","Yes") -> Yes
A35: Coffee | B35: 3 | C35: 2 | D35: 6 | E35: {=_xlfn.IFS(D35<=5, "$1-5", D35<=10, "$6-10",D35<=15,"$11-15", D35<=20, "$16-20", D35>20, "$20+")} -> $6-10 | F35: Unspecified | G35: Unspecified | H35: 44928 | I35: =IFERROR(YEAR(H35), "N/A") -> 2023 | J35: {=IFERROR(TEXT(H35, "[$-en-US]mmm"), _xleta.N/A)} -> Jan | K35: =IFERROR(DAY(H35), "N/A") -> 2 | L35: =IFERROR(TEXT(K35, "[$-en-US]dddd"), "N/A") -> Monday | M35: =IF(AND(H35="Error",F35="Error"), "No","Yes") -> Yes
A36: Cake | B36: 4 | C36: 3 | D36: 12 | E36: {=_xlfn.IFS(D36<=5, "$1-5", D36<=10, "$6-10",D36<=15,"$11-15", D36<=20, "$16-20", D36>20, "$20+")} -> $11-15 | F36: Cash | G36: Error | H36: 44928 | I36: =IFERROR(YEAR(H36), "N/A") -> 2023 | J36: {=IFERROR(TEXT(H36, "[$-en-US]mmm"), _xleta.N/A)} -> Jan | K36: =IFERROR(DAY(H36), "N/A") -> 2 | L36: =IFERROR(TEXT(K36, "[$-en-US]dddd"), "N/A") -> Monday | M36: =IF(AND(H36="Error",F36="Error"), "No","Yes") -> Yes
A37: Sandwich | B37: 4 | C37: 4 | D37: 16 | E37: {=_xlfn.IFS(D37<=5, "$1-5", D37<=10, "$6-10",D37<=15,"$11-15", D37<=20, "$16-20", D37>20, "$20+")} -> $16-20 | F37: Cash | G37: Takeaway | H37: 44928 | I37: =IFERROR(YEAR(H37), "N/A") -> 2023 | J37: {=IFERROR(TEXT(H37, "[$-en-US]mmm"), _xleta.N/A)} -> Jan | K37: =IFERROR(DAY(H37), "N/A") -> 2 | L37: =IFERROR(TEXT(K37, "[$-en-US]dddd"), "N/A") -> Monday | M37: =IF(AND(H37="Error",F37="Error"), "No","Yes") -> Yes
A38: Salad | B38: 2 | C38: 5 | D38: 10 | E38: {=_xlfn.IFS(D38<=5, "$1-5", D38<=10, "$6-10",D38<=15,"$11-15", D38<=20, "$16-20", D38>20, "$20+")} -> $6-10 | F38: Cash | G38: Takeaway | H38: 44928 | I38: =IFERROR(YEAR(H38), "N/A") -> 2023 | J38: {=IFERROR(TEXT(H38, "[$-en-US]mmm"), _xleta.N/A)} -> Jan | K38: =IFERROR(DAY(H38), "N/A") -> 2 | L38: =IFERROR(TEXT(K38, "[$-en-US]dddd"), "N/A") -> Monday | M38: =IF(AND(H38="Error",F38="Error"), "No","Yes") -> Yes
A39: Cake | B39: 1 | C39: 3 | D39: 3 | E39: {=_xlfn.IFS(D39<=5, "$1-5", D39<=10, "$6-10",D39<=15,"$11-15", D39<=20, "$16-20", D39>20, "$20+")} -> $1-5 | F39: Credit Card | G39: Takeaway | H39: 44928 | I39: =IFERROR(YEAR(H39), "N/A") -> 2023 | J39: {=IFERROR(TEXT(H39, "[$-en-US]mmm"), _xleta.N/A)} -> Jan | K39: =IFERROR(DAY(H39), "N/A") -> 2 | L39: =IFERROR(TEXT(K39, "[$-en-US]dddd"), "N/A") -> Monday | M39: =IF(AND(H39="Error",F39="Error"), "No","Yes") -> Yes
A40: Tea | B40: 1 | C40: 1.5 | D40: 1.5 | E40: {=_xlfn.IFS(D40<=5, "$1-5", D40<=10, "$6-10",D40<=15,"$11-15", D40<=20, "$16-20", D40>20, "$20+")} -> $1-5 | F40: Unspecified | G40: Unspecified | H40: 44928 | I40: =IFERROR(YEAR(H40), "N/A") -> 2023 | J40: {=IFERROR(TEXT(H40, "[$-en-US]mmm"), _xleta.N/A)} -> Jan | K40: =IFERROR(DAY(H40), "N/A") -> 2 | L40: =IFERROR(TEXT(K40, "[$-en-US]dddd"), "N/A") -> Monday | M40: =IF(AND(H40="Error",F40="Error"), "No","Yes") -> Yes
...

Sheet Avg Daily Sales (month)
A1: Total Spent | B1: Date | C1: Month | F1: Month | G1: Number of days | H1: Total Sales | M1: 2023 Sales Trend
A2: 10 | B2: 44927 | C2: Jan | F2: January | G2: 31 | H2: =N3/G2 -> 234 | M2: Row Labels | N2: Sum of Total Spent
A3: 9 | B3: 44927 | C3: Jan | F3: February | G3: 28 | H3: =N4/G3 -> 237.28571 | M3: Jan | N3: 7254
A4: 20 | B4: 44927 | C4: Jan | F4: March | G4: 31 | H4: =N5/G4 -> 232.77419 | M4: Feb | N4: 6644
A5: 15 | B5: 44927 | C5: Jan | F5: April | G5: 30 | H5: =N6/G5 -> 239.3 | M5: Mar | N5: 7216
A6: 20 | B6: 44927 | C6: Jan | F6: May | G6: 31 | H6: =N7/G6 -> 224.43548 | M6: Apr | N6: 7179
A7: 4.5 | B7: 44927 | C7: Jan | F7: June | G7: 30 | H7: =N8/G7 -> 245.1 | M7: May | N7: 6957.5
A8: 10 | B8: 44927 | C8: Jan | F8: July | G8: 31 | H8: =N9/G8 -> 221.85484 | M8: Jun | N8: 7353
A9: 10 | B9: 44927 | C9: Jan | F9: August | G9: 31 | H9: =N10/G9 -> 229.43548 | M9: Jul | N9: 6877.5
A10: 12 | B10: 44927 | C10: Jan | F10: September | G10: 30 | H10: =N11/G10 -> 229.03333 | M10: Aug | N10: 7112.5
A11: 4 | B11: 44927 | C11: Jan | F11: October | G11: 31 | H11: =N12/G11 -> 235.93548 | M11: Sep | N11: 6871
A12: 12 | B12: 44927 | C12: Jan | F12: November | G12: 30 | H12: =N13/G12 -> 232.23333 | M12: Oct | N12: 7314
A13: 8 | B13: 44927 | C13: Jan | F13: December | G13: 31 | H13: =N14/G13 -> 231.51613 | M13: Nov | N13: 6967
A14: 2 | B14: 44927 | C14: Jan | M14: Dec | N14: 7177
A15: 4 | B15: 44927 | C15: Jan | M15: Grand Total | N15: 84922.5
A16: 4 | B16: 44927 | C16: Jan
A17: 7.5 | B17: 44927 | C17: Jan | F17: Month | G17: Total Sales
A18: 3 | B18: 44927 | C18: Jan | F18: January | G18: 234 | M18: 2023 Traffic Trend
A19: 4 | B19: 44927 | C19: Jan | F19: February | G19: 237.28571 | M19: Row Labels | N19: Count of Total Spent
A20: 8 | B20: 44927 | C20: Jan | F20: March | G20: 232.77419 | M20: Jan | N20: 818
A21: 9 | B21: 44928 | C21: Jan | F21: April | G21: 239.3 | M21: Feb | N21: 727
A22: 20 | B22: 44928 | C22: Jan | F22: May | G22: 224.43548 | M22: Mar | N22: 827
A23: 4 | B23: 44928 | C23: Jan | F23: June | G23: 245.1 | M23: Apr | N23: 774
A24: 20 | B24: 44928 | C24: Jan | F24: July | G24: 221.85484 | M24: May | N24: 777
A25: 4 | B25: 44928 | C25: Jan | F25: August | G25: 229.43548 | M25: Jun | N25: 818
A26: 10 | B26: 44928 | C26: Jan | F26: September | G26: 229.03333 | M26: Jul | N26: 791
A27: 20 | B27: 44928 | C27: Jan | F27: October | G27: 235.93548 | M27: Aug | N27: 803
A28: 20 | B28: 44928 | C28: Jan | F28: November | G28: 232.23333 | M28: Sep | N28: 788
A29: 8 | B29: 44928 | C29: Jan | F29: December | G29: 231.51613 | M29: Oct | N29: 838
A30: 5 | B30: 44928 | C30: Jan | M30: Nov | N30: 784
A31: 6 | B31: 44928 | C31: Jan | F31: Month | G31: Number of days | H31: Average Daily Traffic | M31: Dec | N31: 795
A32: 8 | B32: 44928 | C32: Jan | F32: January | G32: 31 | H32: =N20/G32 -> 26.387097 | M32: Grand Total | N32: 9540
A33: 3 | B33: 44928 | C33: Jan | F33: February | G33: 28 | H33: =N21/G33 -> 25.964286
A34: 4 | B34: 44928 | C34: Jan | F34: March | G34: 31 | H34: =N22/G34 -> 26.677419
A35: 6 | B35: 44928 | C35: Jan | F35: April | G35: 30 | H35: =N23/G35 -> 25.8
A36: 12 | B36: 44928 | C36: Jan | F36: May | G36: 31 | H36: =N24/G36 -> 25.064516
A37: 16 | B37: 44928 | C37: Jan | F37: June | G37: 30 | H37: =N25/G37 -> 27.266667
A38: 10 | B38: 44928 | C38: Jan | F38: July | G38: 31 | H38: =N26/G38 -> 25.516129
A39: 3 | B39: 44928 | C39: Jan | F39: August | G39: 31 | H39: =N27/G39 -> 25.903226
A40: 1.5 | B40: 44928 | C40: Jan | F40: September | G40: 30 | H40: =N28/G40 -> 26.266667
...

Sheet Potential Sales
A1: Item | B1: Quantity | C1: Price Per Unit | D1: Total Spent | E1: Spent Group | F1: Potential Sales | I1: Potential Sales Increase by pursuring Spent Group $1-5 buy one more item
A2: Juice | B2: 5 | C2: 3 | D2: 15 | E2: $11-15 | F2: =IF(E2="$1-5", D2+3, D2) -> 15 | I2: =(SUM(F:F)-SUM(D:D))/SUM(D:D) -> 0.12369189
A3: Unspecified | B3: 4 | C3: 3 | D3: 12 | E3: $11-15 | F3: =IF(E3="$1-5", D3+3, D3) -> 12
A4: Cake | B4: 4 | C4: 3 | D4: 12 | E4: $11-15 | F4: =IF(E4="$1-5", D4+3, D4) -> 12
A5: Cake | B5: 4 | C5: 3 | D5: 12 | E5: $11-15 | F5: =IF(E5="$1-5", D5+3, D5) -> 12
A6: Cake | B6: 4 | C6: 3 | D6: 12 | E6: $11-15 | F6: =IF(E6="$1-5", D6+3, D6) -> 12
A7: Juice | B7: 4 | C7: 3 | D7: 12 | E7: $11-15 | F7: =IF(E7="$1-5", D7+3, D7) -> 12
A8: Cake | B8: 5 | C8: 3 | D8: 15 | E8: $11-15 | F8: =IF(E8="$1-5", D8+3, D8) -> 15
A9: Juice | B9: 4 | C9: 3 | D9: 12 | E9: $11-15 | F9: =IF(E9="$1-5", D9+3, D9) -> 12
A10: Salad | B10: 3 | C10: 5 | D10: 15 | E10: $11-15 | F10: =IF(E10="$1-5", D10+3, D10) -> 15
A11: Smoothie | B11: 3 | C11: 4 | D11: 12 | E11: $11-15 | F11: =IF(E11="$1-5", D11+3, D11) -> 12
A12: Unspecified | B12: 3 | C12: 4 | D12: 12 | E12: $11-15 | F12: =IF(E12="$1-5", D12+3, D12) -> 12
A13: Juice | B13: 4 | C13: 3 | D13: 12 | E13: $11-15 | F13: =IF(E13="$1-5", D13+3, D13) -> 12
A14: Cake | B14: 5 | C14: 3 | D14: 15 | E14: $11-15 | F14: =IF(E14="$1-5", D14+3, D14) -> 15
... A2147: Tea | B2147: 2 | C2147: 1.5 | D2147: 3 | E2147: $1-5 | F2147: =IF(E2147="$1-5", D2147+3, D2147) -> 6
A2148: Unspecified | B2148: 4 | C2148: Unknown | D2148: 0 | E2148: $1-5 | F2148: =IF(E2148="$1-5", D2148+3, D2148) -> 3
A2149: Smoothie | B2149: 1 | C2149: 4 | D2149: 4 | E2149: $1-5 | F2149: =IF(E2149="$1-5", D2149+3, D2149) -> 7
A2150: Tea | B2150: 3 | C2150: 1.5 | D2150: 4.5 | E2150: $1-5 | F2150: =IF(E2150="$1-5", D2150+3, D2150) -> 7.5
A2151: Coffee | B2151: 1 | C2151: 2 | D2151: 2 | E2151: $1-5 | F2151: =IF(E2151="$1-5", D2151+3, D2151) -> 5
A2152: Cake | B2152: 1 | C2152: 3 | D2152: 3 | E2152: $1-5 | F2152: =IF(E2152="$1-5", D2152+3, D2152) -> 6
A2153: Salad | B2153: 1 | C2153: 5 | D2153: 5 | E2153: $1-5 | F2153: =IF(E2153="$1-5", D2153+3, D2153) -> 8
A2154: Sandwich | B2154: 1 | C2154: 4 | D2154: 4 | E2154: $1-5 | F2154: =IF(E2154="$1-5", D2154+3, D2154) -> 7
A2155: Coffee | B2155: 1 | C2155: 2 | D2155: 2 | E2155: $1-5 | F2155: =IF(E2155="$1-5", D2155+3, D2155) -> 5
A2156: Tea | B2156: 1 | C2156: 1.5 | D2156: 1.5 | E2156: $1-5 | F2156: =IF(E2156="$1-5", D2156+3, D2156) -> 4.5
A2157: Smoothie | B2157: 1 | C2157: 4 | D2157: 4 | E2157: $1-5 | F2157: =IF(E2157="$1-5", D2157+3, D2157) -> 7
A2158: Cookie | B2158: 4 | C2158: 1 | D2158: 4 | E2158: $1-5 | F2158: =IF(E2158="$1-5", D2158+3, D2158) -> 7
A2159: Coffee | B2159: 1 | C2159: 2 | D2159: 2 | E2159: $1-5 | F2159: =IF(E2159="$1-5", D2159+3, D2159) -> 5
A2160: Cookie | B2160: 1 | C2160: 1 | D2160: 1 | E2160: $1-5 | F2160: =IF(E2160="$1-5", D2160+3, D2160) -> 4
... A5066: Coffee | B5066: 2 | C5066: 2 | D5066: 4 | E5066: $1-5 | F5066: =IF(E5066="$1-5", D5066+3, D5066) -> 7
A5067: Unspecified | B5067: 4 | C5067: Unknown | D5067: 0 | E5067: $1-5 | F5067: =IF(E5067="$1-5", D5067+3, D5067) -> 3
A5068: Cookie | B5068: 1 | C5068: 1 | D5068: 1 | E5068: $1-5 | F5068: =IF(E5068="$1-5", D5068+3, D5068) -> 4
A5069: Coffee | B5069: 1 | C5069: 2 | D5069: 2 | E5069: $1-5 | F5069: =IF(E5069="$1-5", D5069+3, D5069) -> 5
A5070: Coffee | B5070: 1 | C5070: 2 | D5070: 2 | E5070: $1-5 | F5070: =IF(E5070="$1-5", D5070+3, D5070) -> 5
A5071: Cookie | B5071: 5 | C5071: 1 | D5071: 5 | E5071: $1-5 | F5071: =IF(E5071="$1-5", D5071+3, D5071) -> 8
A5072: Juice | B5072: 1 | C5072: 3 | D5072: 3 | E5072: $1-5 | F5072: =IF(E5072="$1-5", D5072+3, D5072) -> 6
A5073: Cookie | B5073: 2 | C5073: 1 | D5073: 2 | E5073: $1-5 | F5073: =IF(E5073="$1-5", D5073+3, D5073) -> 5
A5074: Juice | B5074: 1 | C5074: 3 | D5074: 3 | E5074: $1-5 | F5074: =IF(E5074="$1-5", D5074+3, D5074) -> 6
A5075: Cookie | B5075: 1 | C5075: 1 | D5075: 1 | E5075: $1-5 | F5075: =IF(E5075="$1-5", D5075+3, D5075) -> 4
A5076: Cookie | B5076: 5 | C5076: 1 | D5076: 5 | E5076: $1-5 | F5076: =IF(E5076="$1-5", D5076+3, D5076) -> 8
A5077: Tea | B5077: 1 | C5077: 1.5 | D5077: 1.5 | E5077: $1-5 | F5077: =IF(E5077="$1-5", D5077+3, D5077) -> 4.5
...

Sheet Item Price
A1: Item | B1: Item Price
A2: Cookie | B2: 1
A3: Tea | B3: 1.5
A4: Coffee | B4: 2
A5: Cake | B5: 3
A6: Juice | B6: 3
A7: Smoothie | B7: 4
A8: Sandwich | B8: 4
A9: Salad | B9: 5

Sheet SalesPivot
B2: Transcation Complete? | C2: Yes | J2: Transcation Complete? | K2: Yes
B3: Transaction Date | C3: (Multiple Items) | J3: Transaction Date | K3: (Multiple Items)
B4: Month | C4: (All) | J4: 2023 Sales Trend
B5: Monthly Sales | J5: Row Labels | K5: Sum of Total Spent
B6: Row Labels | C6: Sum of Total Spent | J6: Jan | K6: 7254
B7: 1 | C7: 2589.5 | J7: Feb | K7: 6644
B8: 2 | C8: 2688 | J8: Mar | K8: 7216
B9: 3 | C9: 2522 | J9: Apr | K9: 7179
B10: 4 | C10: 2759 | J10: May | K10: 6957.5
B11: 5 | C11: 2643 | J11: Jun | K11: 7353
B12: 6 | C12: 3482 | J12: Jul | K12: 6877.5
B13: 7 | C13: 2896 | J13: Aug | K13: 7112.5
B14: 8 | C14: 2774.5 | J14: Sep | K14: 6871
B15: 9 | C15: 2798 | J15: Oct | K15: 7314
B16: 10 | C16: 2978 | J16: Nov | K16: 6967
B17: 11 | C17: 2464 | J17: Dec | K17: 7177
B18: 12 | C18: 2620 | J18: Grand Total | K18: 84922.5
B19: 13 | C19: 2691.5
B20: 14 | C20: 2607.5
B21: 15 | C21: 2867.5
B22: 16 | C22: 3132.5
B23: 17 | C23: 2715.5 | I23: Transcation Complete? | J23: Yes
B24: 18 | C24: 2908.5 | I24: Transaction Date | J24: (Multiple Items)
B25: 19 | C25: 2775 | I25: Payment Method Comparison
B26: 20 | C26: 3001 | I26: Row Labels | J26: Total Sales
B27: 21 | C27: 3002.5 | I27: Cash | J27: 0.23344872
B28: 22 | C28: 2496 | I28: Credit Card | J28: 0.23474686
B29: 23 | C29: 3036 | I29: Digital Wallet | J29: 0.23766768
B30: 24 | C30: 2749.5 | I30: Unspecified | J30: 0.29413674
B31: 25 | C31: 2652.5 | I31: Grand Total | J31: 1 | N31: Transcation Complete? | O31: Yes
B32: 26 | C32: 2959.5 | N32: Transaction Date | O32: (Multiple Items)
B33: 27 | C33: 2470 | N33: 2023 Traffic Trend
B34: 28 | C34: 2974 | N34: Row Labels | O34: Count of Total Spent
B35: 29 | C35: 2380 | N35: Jan | O35: 818
B36: 30 | C36: 2726.5 | N36: Feb | O36: 727
B37: 31 | C37: 1563 | N37: Mar | O37: 827
B38: Grand Total | C38: 84922.5 | N38: Apr | O38: 774
N39: May | O39: 777
B40: Transcation Complete? | C40: Yes | N40: Jun | O40: 818
B41: Transaction Date | C41: (Multiple Items) | N41: Jul | O41: 791
...

Sheet ItemPivot
B1: Month | C1: Jan | S1: Month | T1: Jan
B2: Monthly Item Sales Volume | S2: Monthly Item Sales Amount
B3: Row Labels | C3: Sum of Quantity | S3: Row Labels | T3: Sales Amount
B4: Cake | C4: 285 | S4: Cake | T4: 855
B5: Coffee | C5: 296 | S5: Coffee | T5: 592
B6: Cookie | C6: 292 | S6: Cookie | T6: 292
B7: Juice | C7: 306 | S7: Juice | T7: 918
B8: Salad | C8: 333 | S8: Salad | T8: 1665
B9: Sandwich | C9: 346 | S9: Sandwich | T9: 1384
B10: Smoothie | C10: 189 | S10: Smoothie | T10: 756
B11: Tea | C11: 304 | S11: Tea | T11: 456
B12: Grand Total | C12: 2351 | S12: Grand Total | T12: 6918
B20: Item | C20: Cake
B21: Item Sales by Month
B22: Row Labels | C22: Sum of Quantity
B23: Jan | C23: 17
B24: Feb | C24: 11
B25: Mar | C25: 27
B26: Apr | C26: 13
B27: May | C27: 13
B28: Jun | C28: 16
B29: Jul | C29: 26
B30: Aug | C30: 11
B31: Sep | C31: 17
B32: Oct | C32: 19
B33: Nov | C33: 21
B34: Dec | C34: 18
B35: Grand Total | C35: 209
B53: Transcation Complete? | C53: Yes
B54: Transaction Date | C54: (Multiple Items)
B55: Average items purchase
B56: Row Labels | C56: Average of Quantity
B57: Cake | C57: 0.9952381
B58: Coffee | C58: 1.4796748
B59: Cookie | C59: 2.9774109
B60: Juice | C60: 0.98623853
B61: Salad | C61: 0.99212598
B62: Sandwich | C62: 0.98095238
B63: Smoothie | C63: 0.99009901
B64: Tea | C64: 2.027417
...

Sheet Dashboard_sales
A1: 2023 Café sales Report
A2: Total Revenue | B2: Average Monthly Sales | C2: Average Daily Sales
A3: $89060.00 | B3: $7421.67 | C3: $244.00
A18: Month | B18: Avgerage Daily Sales | C18: Average Daily Traffic
A19: January | B19: 234 | C19: 26.387097
A20: February | B20: 237.28571 | C20: 25.964286
A21: March | B21: 232.77419 | C21: 26.677419
A22: April | B22: 239.3 | C22: 25.8
A23: May | B23: 224.43548 | C23: 25.064516
A24: June | B24: 245.1 | C24: 27.266667
A25: July | B25: 221.85484 | C25: 25.516129
A26: August | B26: 229.43548 | C26: 25.903226
A27: September | B27: 229.03333 | C27: 26.266667
A28: October | B28: 235.93548 | C28: 27.032258
A29: November | B29: 232.23333 | C29: 26.133333
A30: December | B30: 231.51613 | C30: 25.645161
V37: =153/3 -> 51

Sheet Dashboard_spendinghabit
A1: 2023 Café Spending Habit Report
A2: Best Seller | C2: Highest Sales Item
A3: Coffee | C3: Salad
A11: Spend Group Percentage | C11: Average items purchase per transcation
A12: Spent Group | B12: Percentage | C12: Spent Group | D12: Percentage
A13: $1-5 | B13: 0.36792453 | C13: $1-5 | D13: 1.917094
A14: $6-10 | B14: 0.30503145 | C14: $6-10 | D14: 3.0841924
A15: $11-15 | B15: 0.17400419 | C15: $11-15 | D15: 3.8843373
A16: $16-20 | B16: 0.12578616 | C16: $16-20 | D16: 4.4225
A17: $20+ | B17: 0.027253669 | C17: $20+ | D17: 4.9807692
